2025-01-03 22:16:41,568 - root - INFO - Logging configured with level: INFO and file: app.log
2025-01-03 22:16:55,832 - root - ERROR - 发生错误: property 'event_bus' of 'GlobalState' object has no setter
2025-01-03 22:16:55,833 - root - ERROR - 堆栈跟踪信息:
Traceback (most recent call last):
  File "/Users/lpcw/Documents/PyQt/PyExcelApp/main.py", line 31, in main
    state.event_bus = event_bus  # 使用适配后的事件总线
    ^^^^^^^^^^^^^^^
AttributeError: property 'event_bus' of 'GlobalState' object has no setter

2025-01-03 22:18:54,217 - root - INFO - Logging configured with level: INFO and file: app.log
2025-01-03 22:18:54,991 - plugin_manager.utils.plugin_loader - INFO - 找到 2 个插件: ['xzltxs_test', 'xzltxs']
2025-01-03 22:19:12,981 - root - ERROR - 发生错误: 'SecurityScanner' object has no attribute 'start_periodic_check'
2025-01-03 22:19:12,981 - root - ERROR - 堆栈跟踪信息:
Traceback (most recent call last):
  File "/Users/lpcw/Documents/PyQt/PyExcelApp/main.py", line 51, in main
    security_scanner.start_periodic_check()
    ^^^^^^^^^^^^^^^^^^^^^^^^^^^^^^^^^^^^^
AttributeError: 'SecurityScanner' object has no attribute 'start_periodic_check'

2025-01-03 22:21:47,831 - root - INFO - Logging configured with level: INFO and file: app.log
2025-01-03 22:21:48,622 - plugin_manager.utils.plugin_loader - INFO - 找到 2 个插件: ['xzltxs_test', 'xzltxs']
2025-01-03 22:21:58,711 - root - ERROR - 发生错误: Invalid URL 'None/security/scan': No scheme supplied. Perhaps you meant https://None/security/scan?
2025-01-03 22:21:58,711 - root - ERROR - 堆栈跟踪信息:
Traceback (most recent call last):
  File "/Users/lpcw/Documents/PyQt/PyExcelApp/main.py", line 51, in main
    security_scanner.check()
  File "/Users/lpcw/Documents/PyQt/PyExcelApp/dependency_monitoring_framework/src/services/security_scanner.py", line 17, in check
    response = requests.get(
               ^^^^^^^^^^^^^
  File "/Volumes/TOSHIBAEXT/opt/anaconda3/envs/pyqt/lib/python3.11/site-packages/requests/api.py", line 73, in get
    return request("get", url, params=params, **kwargs)
           ^^^^^^^^^^^^^^^^^^^^^^^^^^^^^^^^^^^^^^^^^^^^
  File "/Volumes/TOSHIBAEXT/opt/anaconda3/envs/pyqt/lib/python3.11/site-packages/requests/api.py", line 59, in request
    return session.request(method=method, url=url, **kwargs)
           ^^^^^^^^^^^^^^^^^^^^^^^^^^^^^^^^^^^^^^^^^^^^^^^^^
  File "/Volumes/TOSHIBAEXT/opt/anaconda3/envs/pyqt/lib/python3.11/site-packages/requests/sessions.py", line 575, in request
    prep = self.prepare_request(req)
           ^^^^^^^^^^^^^^^^^^^^^^^^^
  File "/Volumes/TOSHIBAEXT/opt/anaconda3/envs/pyqt/lib/python3.11/site-packages/requests/sessions.py", line 484, in prepare_request
    p.prepare(
  File "/Volumes/TOSHIBAEXT/opt/anaconda3/envs/pyqt/lib/python3.11/site-packages/requests/models.py", line 367, in prepare
    self.prepare_url(url, params)
  File "/Volumes/TOSHIBAEXT/opt/anaconda3/envs/pyqt/lib/python3.11/site-packages/requests/models.py", line 438, in prepare_url
    raise MissingSchema(
requests.exceptions.MissingSchema: Invalid URL 'None/security/scan': No scheme supplied. Perhaps you meant https://None/security/scan?

2025-01-03 22:41:00,458 - root - INFO - Logging configured with level: INFO and file: app.log
2025-01-03 22:41:01,621 - plugin_manager.utils.plugin_loader - INFO - 找到 2 个插件: ['xzltxs_test', 'xzltxs']
2025-01-03 22:41:16,113 - root - ERROR - 发生错误: Invalid URL 'None/security/scan': No scheme supplied. Perhaps you meant https://None/security/scan?
2025-01-03 22:41:16,114 - root - ERROR - 堆栈跟踪信息:
Traceback (most recent call last):
  File "/Users/lpcw/Documents/PyQt/PyExcelApp/main.py", line 51, in main
    security_scanner.check()
  File "/Users/lpcw/Documents/PyQt/PyExcelApp/dependency_monitoring_framework/src/services/security_scanner.py", line 17, in check
    response = requests.get(
               ^^^^^^^^^^^^^
  File "/Volumes/TOSHIBAEXT/opt/anaconda3/envs/pyqt/lib/python3.11/site-packages/requests/api.py", line 73, in get
    return request("get", url, params=params, **kwargs)
           ^^^^^^^^^^^^^^^^^^^^^^^^^^^^^^^^^^^^^^^^^^^^
  File "/Volumes/TOSHIBAEXT/opt/anaconda3/envs/pyqt/lib/python3.11/site-packages/requests/api.py", line 59, in request
    return session.request(method=method, url=url, **kwargs)
           ^^^^^^^^^^^^^^^^^^^^^^^^^^^^^^^^^^^^^^^^^^^^^^^^^
  File "/Volumes/TOSHIBAEXT/opt/anaconda3/envs/pyqt/lib/python3.11/site-packages/requests/sessions.py", line 575, in request
    prep = self.prepare_request(req)
           ^^^^^^^^^^^^^^^^^^^^^^^^^
  File "/Volumes/TOSHIBAEXT/opt/anaconda3/envs/pyqt/lib/python3.11/site-packages/requests/sessions.py", line 484, in prepare_request
    p.prepare(
  File "/Volumes/TOSHIBAEXT/opt/anaconda3/envs/pyqt/lib/python3.11/site-packages/requests/models.py", line 367, in prepare
    self.prepare_url(url, params)
  File "/Volumes/TOSHIBAEXT/opt/anaconda3/envs/pyqt/lib/python3.11/site-packages/requests/models.py", line 438, in prepare_url
    raise MissingSchema(
requests.exceptions.MissingSchema: Invalid URL 'None/security/scan': No scheme supplied. Perhaps you meant https://None/security/scan?

2025-01-03 22:43:50,273 - root - INFO - Logging configured with level: INFO and file: app.log
2025-01-03 22:43:51,158 - plugin_manager.utils.plugin_loader - INFO - 找到 2 个插件: ['xzltxs_test', 'xzltxs']
2025-01-03 22:44:08,283 - root - ERROR - 发生错误: Invalid URL 'None/security/scan': No scheme supplied. Perhaps you meant https://None/security/scan?
2025-01-03 22:44:08,284 - root - ERROR - 堆栈跟踪信息:
Traceback (most recent call last):
  File "/Users/lpcw/Documents/PyQt/PyExcelApp/main.py", line 51, in main
    security_scanner.check()
  File "/Users/lpcw/Documents/PyQt/PyExcelApp/dependency_monitoring_framework/src/services/security_scanner.py", line 17, in check
    response = requests.get(
               ^^^^^^^^^^^^^
  File "/Volumes/TOSHIBAEXT/opt/anaconda3/envs/pyqt/lib/python3.11/site-packages/requests/api.py", line 73, in get
    return request("get", url, params=params, **kwargs)
           ^^^^^^^^^^^^^^^^^^^^^^^^^^^^^^^^^^^^^^^^^^^^
  File "/Volumes/TOSHIBAEXT/opt/anaconda3/envs/pyqt/lib/python3.11/site-packages/requests/api.py", line 59, in request
    return session.request(method=method, url=url, **kwargs)
           ^^^^^^^^^^^^^^^^^^^^^^^^^^^^^^^^^^^^^^^^^^^^^^^^^
  File "/Volumes/TOSHIBAEXT/opt/anaconda3/envs/pyqt/lib/python3.11/site-packages/requests/sessions.py", line 575, in request
    prep = self.prepare_request(req)
           ^^^^^^^^^^^^^^^^^^^^^^^^^
  File "/Volumes/TOSHIBAEXT/opt/anaconda3/envs/pyqt/lib/python3.11/site-packages/requests/sessions.py", line 484, in prepare_request
    p.prepare(
  File "/Volumes/TOSHIBAEXT/opt/anaconda3/envs/pyqt/lib/python3.11/site-packages/requests/models.py", line 367, in prepare
    self.prepare_url(url, params)
  File "/Volumes/TOSHIBAEXT/opt/anaconda3/envs/pyqt/lib/python3.11/site-packages/requests/models.py", line 438, in prepare_url
    raise MissingSchema(
requests.exceptions.MissingSchema: Invalid URL 'None/security/scan': No scheme supplied. Perhaps you meant https://None/security/scan?

2025-01-03 22:48:44,964 - root - INFO - Logging configured with level: INFO and file: app.log
2025-01-03 22:48:45,796 - plugin_manager.utils.plugin_loader - INFO - 找到 2 个插件: ['xzltxs_test', 'xzltxs']
2025-01-03 22:48:51,742 - root - ERROR - 发生错误: Invalid URL 'None/security/scan': No scheme supplied. Perhaps you meant https://None/security/scan?
2025-01-03 22:48:51,742 - root - ERROR - 堆栈跟踪信息:
Traceback (most recent call last):
  File "/Users/lpcw/Documents/PyQt/PyExcelApp/main.py", line 51, in main
    security_scanner.check()
  File "/Users/lpcw/Documents/PyQt/PyExcelApp/dependency_monitoring_framework/src/services/security_scanner.py", line 17, in check
    response = requests.get(
               ^^^^^^^^^^^^^
  File "/Volumes/TOSHIBAEXT/opt/anaconda3/envs/pyqt/lib/python3.11/site-packages/requests/api.py", line 73, in get
    return request("get", url, params=params, **kwargs)
           ^^^^^^^^^^^^^^^^^^^^^^^^^^^^^^^^^^^^^^^^^^^^
  File "/Volumes/TOSHIBAEXT/opt/anaconda3/envs/pyqt/lib/python3.11/site-packages/requests/api.py", line 59, in request
    return session.request(method=method, url=url, **kwargs)
           ^^^^^^^^^^^^^^^^^^^^^^^^^^^^^^^^^^^^^^^^^^^^^^^^^
  File "/Volumes/TOSHIBAEXT/opt/anaconda3/envs/pyqt/lib/python3.11/site-packages/requests/sessions.py", line 575, in request
    prep = self.prepare_request(req)
           ^^^^^^^^^^^^^^^^^^^^^^^^^
  File "/Volumes/TOSHIBAEXT/opt/anaconda3/envs/pyqt/lib/python3.11/site-packages/requests/sessions.py", line 484, in prepare_request
    p.prepare(
  File "/Volumes/TOSHIBAEXT/opt/anaconda3/envs/pyqt/lib/python3.11/site-packages/requests/models.py", line 367, in prepare
    self.prepare_url(url, params)
  File "/Volumes/TOSHIBAEXT/opt/anaconda3/envs/pyqt/lib/python3.11/site-packages/requests/models.py", line 438, in prepare_url
    raise MissingSchema(
requests.exceptions.MissingSchema: Invalid URL 'None/security/scan': No scheme supplied. Perhaps you meant https://None/security/scan?

2025-01-03 23:09:00,264 - root - INFO - Logging configured with level: INFO and file: logs/app.log
2025-01-03 23:09:01,379 - plugin_manager.utils.plugin_loader - INFO - 找到 2 个插件: ['xzltxs_test', 'xzltxs']
2025-01-03 23:09:05,373 - root - ERROR - 发生错误: Invalid URL 'None/security/scan': No scheme supplied. Perhaps you meant https://None/security/scan?
2025-01-03 23:09:05,376 - root - ERROR - 堆栈跟踪信息:
Traceback (most recent call last):
  File "/Users/lpcw/Documents/PyQt/PyExcelApp/main.py", line 51, in main
    security_scanner.check()
  File "/Users/lpcw/Documents/PyQt/PyExcelApp/dependency_monitoring_framework/src/services/security_scanner.py", line 17, in check
    response = requests.get(
               ^^^^^^^^^^^^^
  File "/Volumes/TOSHIBAEXT/opt/anaconda3/envs/pyqt/lib/python3.11/site-packages/requests/api.py", line 73, in get
    return request("get", url, params=params, **kwargs)
           ^^^^^^^^^^^^^^^^^^^^^^^^^^^^^^^^^^^^^^^^^^^^
  File "/Volumes/TOSHIBAEXT/opt/anaconda3/envs/pyqt/lib/python3.11/site-packages/requests/api.py", line 59, in request
    return session.request(method=method, url=url, **kwargs)
           ^^^^^^^^^^^^^^^^^^^^^^^^^^^^^^^^^^^^^^^^^^^^^^^^^
  File "/Volumes/TOSHIBAEXT/opt/anaconda3/envs/pyqt/lib/python3.11/site-packages/requests/sessions.py", line 575, in request
    prep = self.prepare_request(req)
           ^^^^^^^^^^^^^^^^^^^^^^^^^
  File "/Volumes/TOSHIBAEXT/opt/anaconda3/envs/pyqt/lib/python3.11/site-packages/requests/sessions.py", line 484, in prepare_request
    p.prepare(
  File "/Volumes/TOSHIBAEXT/opt/anaconda3/envs/pyqt/lib/python3.11/site-packages/requests/models.py", line 367, in prepare
    self.prepare_url(url, params)
  File "/Volumes/TOSHIBAEXT/opt/anaconda3/envs/pyqt/lib/python3.11/site-packages/requests/models.py", line 438, in prepare_url
    raise MissingSchema(
requests.exceptions.MissingSchema: Invalid URL 'None/security/scan': No scheme supplied. Perhaps you meant https://None/security/scan?

2025-01-03 23:11:22,007 - root - INFO - Logging configured with level: INFO and file: logs/app.log
2025-01-03 23:11:22,841 - plugin_manager.utils.plugin_loader - INFO - 找到 2 个插件: ['xzltxs_test', 'xzltxs']
2025-01-03 23:11:34,851 - root - ERROR - 发生错误: HTTPConnectionPool(host='test', port=80): Max retries exceeded with url: /security/scan (Caused by NameResolutionError("<urllib3.connection.HTTPConnection object at 0x11cd18710>: Failed to resolve 'test' ([Errno 8] nodename nor servname provided, or not known)"))
2025-01-03 23:11:34,852 - root - ERROR - 堆栈跟踪信息:
Traceback (most recent call last):
  File "/Volumes/TOSHIBAEXT/opt/anaconda3/envs/pyqt/lib/python3.11/site-packages/urllib3/connection.py", line 199, in _new_conn
    sock = connection.create_connection(
           ^^^^^^^^^^^^^^^^^^^^^^^^^^^^^
  File "/Volumes/TOSHIBAEXT/opt/anaconda3/envs/pyqt/lib/python3.11/site-packages/urllib3/util/connection.py", line 60, in create_connection
    for res in socket.getaddrinfo(host, port, family, socket.SOCK_STREAM):
               ^^^^^^^^^^^^^^^^^^^^^^^^^^^^^^^^^^^^^^^^^^^^^^^^^^^^^^^^^^
  File "/Volumes/TOSHIBAEXT/opt/anaconda3/envs/pyqt/lib/python3.11/socket.py", line 974, in getaddrinfo
    for res in _socket.getaddrinfo(host, port, family, type, proto, flags):
               ^^^^^^^^^^^^^^^^^^^^^^^^^^^^^^^^^^^^^^^^^^^^^^^^^^^^^^^^^^^
socket.gaierror: [Errno 8] nodename nor servname provided, or not known

The above exception was the direct cause of the following exception:

Traceback (most recent call last):
  File "/Volumes/TOSHIBAEXT/opt/anaconda3/envs/pyqt/lib/python3.11/site-packages/urllib3/connectionpool.py", line 789, in urlopen
    response = self._make_request(
               ^^^^^^^^^^^^^^^^^^^
  File "/Volumes/TOSHIBAEXT/opt/anaconda3/envs/pyqt/lib/python3.11/site-packages/urllib3/connectionpool.py", line 495, in _make_request
    conn.request(
  File "/Volumes/TOSHIBAEXT/opt/anaconda3/envs/pyqt/lib/python3.11/site-packages/urllib3/connection.py", line 441, in request
    self.endheaders()
  File "/Volumes/TOSHIBAEXT/opt/anaconda3/envs/pyqt/lib/python3.11/http/client.py", line 1298, in endheaders
    self._send_output(message_body, encode_chunked=encode_chunked)
  File "/Volumes/TOSHIBAEXT/opt/anaconda3/envs/pyqt/lib/python3.11/http/client.py", line 1058, in _send_output
    self.send(msg)
  File "/Volumes/TOSHIBAEXT/opt/anaconda3/envs/pyqt/lib/python3.11/http/client.py", line 996, in send
    self.connect()
  File "/Volumes/TOSHIBAEXT/opt/anaconda3/envs/pyqt/lib/python3.11/site-packages/urllib3/connection.py", line 279, in connect
    self.sock = self._new_conn()
                ^^^^^^^^^^^^^^^^
  File "/Volumes/TOSHIBAEXT/opt/anaconda3/envs/pyqt/lib/python3.11/site-packages/urllib3/connection.py", line 206, in _new_conn
    raise NameResolutionError(self.host, self, e) from e
urllib3.exceptions.NameResolutionError: <urllib3.connection.HTTPConnection object at 0x11cd18710>: Failed to resolve 'test' ([Errno 8] nodename nor servname provided, or not known)

The above exception was the direct cause of the following exception:

Traceback (most recent call last):
  File "/Volumes/TOSHIBAEXT/opt/anaconda3/envs/pyqt/lib/python3.11/site-packages/requests/adapters.py", line 667, in send
    resp = conn.urlopen(
           ^^^^^^^^^^^^^
  File "/Volumes/TOSHIBAEXT/opt/anaconda3/envs/pyqt/lib/python3.11/site-packages/urllib3/connectionpool.py", line 843, in urlopen
    retries = retries.increment(
              ^^^^^^^^^^^^^^^^^^
  File "/Volumes/TOSHIBAEXT/opt/anaconda3/envs/pyqt/lib/python3.11/site-packages/urllib3/util/retry.py", line 519, in increment
    raise MaxRetryError(_pool, url, reason) from reason  # type: ignore[arg-type]
    ^^^^^^^^^^^^^^^^^^^^^^^^^^^^^^^^^^^^^^^^^^^^^^^^^^^
urllib3.exceptions.MaxRetryError: HTTPConnectionPool(host='test', port=80): Max retries exceeded with url: /security/scan (Caused by NameResolutionError("<urllib3.connection.HTTPConnection object at 0x11cd18710>: Failed to resolve 'test' ([Errno 8] nodename nor servname provided, or not known)"))

During handling of the above exception, another exception occurred:

Traceback (most recent call last):
  File "/Users/lpcw/Documents/PyQt/PyExcelApp/main.py", line 51, in main
    security_scanner.check()
  File "/Users/lpcw/Documents/PyQt/PyExcelApp/dependency_monitoring_framework/src/services/security_scanner.py", line 17, in check
    response = requests.get(
               ^^^^^^^^^^^^^
  File "/Volumes/TOSHIBAEXT/opt/anaconda3/envs/pyqt/lib/python3.11/site-packages/requests/api.py", line 73, in get
    return request("get", url, params=params, **kwargs)
           ^^^^^^^^^^^^^^^^^^^^^^^^^^^^^^^^^^^^^^^^^^^^
  File "/Volumes/TOSHIBAEXT/opt/anaconda3/envs/pyqt/lib/python3.11/site-packages/requests/api.py", line 59, in request
    return session.request(method=method, url=url, **kwargs)
           ^^^^^^^^^^^^^^^^^^^^^^^^^^^^^^^^^^^^^^^^^^^^^^^^^
  File "/Volumes/TOSHIBAEXT/opt/anaconda3/envs/pyqt/lib/python3.11/site-packages/requests/sessions.py", line 589, in request
    resp = self.send(prep, **send_kwargs)
           ^^^^^^^^^^^^^^^^^^^^^^^^^^^^^^
  File "/Volumes/TOSHIBAEXT/opt/anaconda3/envs/pyqt/lib/python3.11/site-packages/requests/sessions.py", line 703, in send
    r = adapter.send(request, **kwargs)
        ^^^^^^^^^^^^^^^^^^^^^^^^^^^^^^^
  File "/Volumes/TOSHIBAEXT/opt/anaconda3/envs/pyqt/lib/python3.11/site-packages/requests/adapters.py", line 700, in send
    raise ConnectionError(e, request=request)
requests.exceptions.ConnectionError: HTTPConnectionPool(host='test', port=80): Max retries exceeded with url: /security/scan (Caused by NameResolutionError("<urllib3.connection.HTTPConnection object at 0x11cd18710>: Failed to resolve 'test' ([Errno 8] nodename nor servname provided, or not known)"))

2025-01-03 23:12:52,992 - root - INFO - Logging configured with level: INFO and file: logs/app.log
2025-01-03 23:12:53,755 - plugin_manager.utils.plugin_loader - INFO - 找到 2 个插件: ['xzltxs_test', 'xzltxs']
2025-01-03 23:13:02,393 - root - ERROR - 发生错误: HTTPConnectionPool(host='localhost', port=8000): Max retries exceeded with url: /security/scan (Caused by NewConnectionError('<urllib3.connection.HTTPConnection object at 0x119f30a50>: Failed to establish a new connection: [Errno 61] Connection refused'))
2025-01-03 23:13:02,394 - root - ERROR - 堆栈跟踪信息:
Traceback (most recent call last):
  File "/Volumes/TOSHIBAEXT/opt/anaconda3/envs/pyqt/lib/python3.11/site-packages/urllib3/connection.py", line 199, in _new_conn
    sock = connection.create_connection(
           ^^^^^^^^^^^^^^^^^^^^^^^^^^^^^
  File "/Volumes/TOSHIBAEXT/opt/anaconda3/envs/pyqt/lib/python3.11/site-packages/urllib3/util/connection.py", line 85, in create_connection
    raise err
  File "/Volumes/TOSHIBAEXT/opt/anaconda3/envs/pyqt/lib/python3.11/site-packages/urllib3/util/connection.py", line 73, in create_connection
    sock.connect(sa)
ConnectionRefusedError: [Errno 61] Connection refused

The above exception was the direct cause of the following exception:

Traceback (most recent call last):
  File "/Volumes/TOSHIBAEXT/opt/anaconda3/envs/pyqt/lib/python3.11/site-packages/urllib3/connectionpool.py", line 789, in urlopen
    response = self._make_request(
               ^^^^^^^^^^^^^^^^^^^
  File "/Volumes/TOSHIBAEXT/opt/anaconda3/envs/pyqt/lib/python3.11/site-packages/urllib3/connectionpool.py", line 495, in _make_request
    conn.request(
  File "/Volumes/TOSHIBAEXT/opt/anaconda3/envs/pyqt/lib/python3.11/site-packages/urllib3/connection.py", line 441, in request
    self.endheaders()
  File "/Volumes/TOSHIBAEXT/opt/anaconda3/envs/pyqt/lib/python3.11/http/client.py", line 1298, in endheaders
    self._send_output(message_body, encode_chunked=encode_chunked)
  File "/Volumes/TOSHIBAEXT/opt/anaconda3/envs/pyqt/lib/python3.11/http/client.py", line 1058, in _send_output
    self.send(msg)
  File "/Volumes/TOSHIBAEXT/opt/anaconda3/envs/pyqt/lib/python3.11/http/client.py", line 996, in send
    self.connect()
  File "/Volumes/TOSHIBAEXT/opt/anaconda3/envs/pyqt/lib/python3.11/site-packages/urllib3/connection.py", line 279, in connect
    self.sock = self._new_conn()
                ^^^^^^^^^^^^^^^^
  File "/Volumes/TOSHIBAEXT/opt/anaconda3/envs/pyqt/lib/python3.11/site-packages/urllib3/connection.py", line 214, in _new_conn
    raise NewConnectionError(
urllib3.exceptions.NewConnectionError: <urllib3.connection.HTTPConnection object at 0x119f30a50>: Failed to establish a new connection: [Errno 61] Connection refused

The above exception was the direct cause of the following exception:

Traceback (most recent call last):
  File "/Volumes/TOSHIBAEXT/opt/anaconda3/envs/pyqt/lib/python3.11/site-packages/requests/adapters.py", line 667, in send
    resp = conn.urlopen(
           ^^^^^^^^^^^^^
  File "/Volumes/TOSHIBAEXT/opt/anaconda3/envs/pyqt/lib/python3.11/site-packages/urllib3/connectionpool.py", line 843, in urlopen
    retries = retries.increment(
              ^^^^^^^^^^^^^^^^^^
  File "/Volumes/TOSHIBAEXT/opt/anaconda3/envs/pyqt/lib/python3.11/site-packages/urllib3/util/retry.py", line 519, in increment
    raise MaxRetryError(_pool, url, reason) from reason  # type: ignore[arg-type]
    ^^^^^^^^^^^^^^^^^^^^^^^^^^^^^^^^^^^^^^^^^^^^^^^^^^^
urllib3.exceptions.MaxRetryError: HTTPConnectionPool(host='localhost', port=8000): Max retries exceeded with url: /security/scan (Caused by NewConnectionError('<urllib3.connection.HTTPConnection object at 0x119f30a50>: Failed to establish a new connection: [Errno 61] Connection refused'))

During handling of the above exception, another exception occurred:

Traceback (most recent call last):
  File "/Users/lpcw/Documents/PyQt/PyExcelApp/main.py", line 51, in main
    security_scanner.check()
  File "/Users/lpcw/Documents/PyQt/PyExcelApp/dependency_monitoring_framework/src/services/security_scanner.py", line 17, in check
    response = requests.get(
               ^^^^^^^^^^^^^
  File "/Volumes/TOSHIBAEXT/opt/anaconda3/envs/pyqt/lib/python3.11/site-packages/requests/api.py", line 73, in get
    return request("get", url, params=params, **kwargs)
           ^^^^^^^^^^^^^^^^^^^^^^^^^^^^^^^^^^^^^^^^^^^^
  File "/Volumes/TOSHIBAEXT/opt/anaconda3/envs/pyqt/lib/python3.11/site-packages/requests/api.py", line 59, in request
    return session.request(method=method, url=url, **kwargs)
           ^^^^^^^^^^^^^^^^^^^^^^^^^^^^^^^^^^^^^^^^^^^^^^^^^
  File "/Volumes/TOSHIBAEXT/opt/anaconda3/envs/pyqt/lib/python3.11/site-packages/requests/sessions.py", line 589, in request
    resp = self.send(prep, **send_kwargs)
           ^^^^^^^^^^^^^^^^^^^^^^^^^^^^^^
  File "/Volumes/TOSHIBAEXT/opt/anaconda3/envs/pyqt/lib/python3.11/site-packages/requests/sessions.py", line 703, in send
    r = adapter.send(request, **kwargs)
        ^^^^^^^^^^^^^^^^^^^^^^^^^^^^^^^
  File "/Volumes/TOSHIBAEXT/opt/anaconda3/envs/pyqt/lib/python3.11/site-packages/requests/adapters.py", line 700, in send
    raise ConnectionError(e, request=request)
requests.exceptions.ConnectionError: HTTPConnectionPool(host='localhost', port=8000): Max retries exceeded with url: /security/scan (Caused by NewConnectionError('<urllib3.connection.HTTPConnection object at 0x119f30a50>: Failed to establish a new connection: [Errno 61] Connection refused'))

2025-01-03 23:13:42,002 - root - INFO - Logging configured with level: INFO and file: logs/app.log
2025-01-03 23:13:42,881 - plugin_manager.utils.plugin_loader - INFO - 找到 2 个插件: ['xzltxs_test', 'xzltxs']
2025-01-03 23:13:57,871 - root - ERROR - 发生错误: 404 Client Error: Not Found for url: https://www.bing.com/security/scan
2025-01-03 23:13:57,871 - root - ERROR - 堆栈跟踪信息:
Traceback (most recent call last):
  File "/Users/lpcw/Documents/PyQt/PyExcelApp/main.py", line 51, in main
    security_scanner.check()
  File "/Users/lpcw/Documents/PyQt/PyExcelApp/dependency_monitoring_framework/src/services/security_scanner.py", line 21, in check
    response.raise_for_status()
  File "/Volumes/TOSHIBAEXT/opt/anaconda3/envs/pyqt/lib/python3.11/site-packages/requests/models.py", line 1024, in raise_for_status
    raise HTTPError(http_error_msg, response=self)
requests.exceptions.HTTPError: 404 Client Error: Not Found for url: https://www.bing.com/security/scan

2025-01-03 23:18:15,947 - root - INFO - Logging configured with level: INFO and file: logs/app.log
2025-01-03 23:18:16,774 - plugin_manager.utils.plugin_loader - INFO - 找到 2 个插件: ['xzltxs_test', 'xzltxs']
2025-01-03 23:18:26,583 - root - ERROR - 发生错误: Expecting value: line 1 column 1 (char 0)
2025-01-03 23:18:26,585 - root - ERROR - 堆栈跟踪信息:
Traceback (most recent call last):
  File "/Volumes/TOSHIBAEXT/opt/anaconda3/envs/pyqt/lib/python3.11/site-packages/requests/models.py", line 974, in json
    return complexjson.loads(self.text, **kwargs)
           ^^^^^^^^^^^^^^^^^^^^^^^^^^^^^^^^^^^^^^
  File "/Volumes/TOSHIBAEXT/opt/anaconda3/envs/pyqt/lib/python3.11/json/__init__.py", line 346, in loads
    return _default_decoder.decode(s)
           ^^^^^^^^^^^^^^^^^^^^^^^^^^
  File "/Volumes/TOSHIBAEXT/opt/anaconda3/envs/pyqt/lib/python3.11/json/decoder.py", line 337, in decode
    obj, end = self.raw_decode(s, idx=_w(s, 0).end())
               ^^^^^^^^^^^^^^^^^^^^^^^^^^^^^^^^^^^^^^
  File "/Volumes/TOSHIBAEXT/opt/anaconda3/envs/pyqt/lib/python3.11/json/decoder.py", line 355, in raw_decode
    raise JSONDecodeError("Expecting value", s, err.value) from None
json.decoder.JSONDecodeError: Expecting value: line 1 column 1 (char 0)

During handling of the above exception, another exception occurred:

Traceback (most recent call last):
  File "/Users/lpcw/Documents/PyQt/PyExcelApp/main.py", line 51, in main
    security_scanner.check()
  File "/Users/lpcw/Documents/PyQt/PyExcelApp/dependency_monitoring_framework/src/services/security_scanner.py", line 28, in check
    return response.json()
           ^^^^^^^^^^^^^^^
  File "/Volumes/TOSHIBAEXT/opt/anaconda3/envs/pyqt/lib/python3.11/site-packages/requests/models.py", line 978, in json
    raise RequestsJSONDecodeError(e.msg, e.doc, e.pos)
requests.exceptions.JSONDecodeError: Expecting value: line 1 column 1 (char 0)

2025-01-03 23:43:59,608 - root - INFO - Logging configured with level: INFO and file: logs/app.log
2025-01-03 23:44:00,550 - plugin_manager.utils.plugin_loader - INFO - 找到 2 个插件: ['xzltxs_test', 'xzltxs']
2025-01-03 23:44:08,691 - root - ERROR - 发生错误: Invalid URL 'None/security/scan': No scheme supplied. Perhaps you meant https://None/security/scan?
2025-01-03 23:44:08,692 - root - ERROR - 堆栈跟踪信息:
Traceback (most recent call last):
  File "/Users/lpcw/Documents/PyQt/PyExcelApp/main.py", line 51, in main
    security_scanner.check()
  File "/Users/lpcw/Documents/PyQt/PyExcelApp/dependency_monitoring_framework/src/services/security_scanner.py", line 17, in check
    response = requests.get(
               ^^^^^^^^^^^^^
  File "/Volumes/TOSHIBAEXT/opt/anaconda3/envs/pyqt/lib/python3.11/site-packages/requests/api.py", line 73, in get
    return request("get", url, params=params, **kwargs)
           ^^^^^^^^^^^^^^^^^^^^^^^^^^^^^^^^^^^^^^^^^^^^
  File "/Volumes/TOSHIBAEXT/opt/anaconda3/envs/pyqt/lib/python3.11/site-packages/requests/api.py", line 59, in request
    return session.request(method=method, url=url, **kwargs)
           ^^^^^^^^^^^^^^^^^^^^^^^^^^^^^^^^^^^^^^^^^^^^^^^^^
  File "/Volumes/TOSHIBAEXT/opt/anaconda3/envs/pyqt/lib/python3.11/site-packages/requests/sessions.py", line 575, in request
    prep = self.prepare_request(req)
           ^^^^^^^^^^^^^^^^^^^^^^^^^
  File "/Volumes/TOSHIBAEXT/opt/anaconda3/envs/pyqt/lib/python3.11/site-packages/requests/sessions.py", line 484, in prepare_request
    p.prepare(
  File "/Volumes/TOSHIBAEXT/opt/anaconda3/envs/pyqt/lib/python3.11/site-packages/requests/models.py", line 367, in prepare
    self.prepare_url(url, params)
  File "/Volumes/TOSHIBAEXT/opt/anaconda3/envs/pyqt/lib/python3.11/site-packages/requests/models.py", line 438, in prepare_url
    raise MissingSchema(
requests.exceptions.MissingSchema: Invalid URL 'None/security/scan': No scheme supplied. Perhaps you meant https://None/security/scan?

2025-01-03 23:50:47,709 - root - INFO - Logging configured with level: INFO and file: logs/app.log
2025-01-03 23:50:48,577 - plugin_manager.utils.plugin_loader - INFO - 找到 2 个插件: ['xzltxs_test', 'xzltxs']
2025-01-03 23:51:15,971 - root - ERROR - 发生错误: HTTPConnectionPool(host='localhost', port=8000): Max retries exceeded with url: /security/scan (Caused by NewConnectionError('<urllib3.connection.HTTPConnection object at 0x117cac710>: Failed to establish a new connection: [Errno 61] Connection refused'))
2025-01-03 23:51:15,974 - root - ERROR - 堆栈跟踪信息:
Traceback (most recent call last):
  File "/Volumes/TOSHIBAEXT/opt/anaconda3/envs/pyqt/lib/python3.11/site-packages/urllib3/connection.py", line 199, in _new_conn
    sock = connection.create_connection(
           ^^^^^^^^^^^^^^^^^^^^^^^^^^^^^
  File "/Volumes/TOSHIBAEXT/opt/anaconda3/envs/pyqt/lib/python3.11/site-packages/urllib3/util/connection.py", line 85, in create_connection
    raise err
  File "/Volumes/TOSHIBAEXT/opt/anaconda3/envs/pyqt/lib/python3.11/site-packages/urllib3/util/connection.py", line 73, in create_connection
    sock.connect(sa)
ConnectionRefusedError: [Errno 61] Connection refused

The above exception was the direct cause of the following exception:

Traceback (most recent call last):
  File "/Volumes/TOSHIBAEXT/opt/anaconda3/envs/pyqt/lib/python3.11/site-packages/urllib3/connectionpool.py", line 789, in urlopen
    response = self._make_request(
               ^^^^^^^^^^^^^^^^^^^
  File "/Volumes/TOSHIBAEXT/opt/anaconda3/envs/pyqt/lib/python3.11/site-packages/urllib3/connectionpool.py", line 495, in _make_request
    conn.request(
  File "/Volumes/TOSHIBAEXT/opt/anaconda3/envs/pyqt/lib/python3.11/site-packages/urllib3/connection.py", line 441, in request
    self.endheaders()
  File "/Volumes/TOSHIBAEXT/opt/anaconda3/envs/pyqt/lib/python3.11/http/client.py", line 1298, in endheaders
    self._send_output(message_body, encode_chunked=encode_chunked)
  File "/Volumes/TOSHIBAEXT/opt/anaconda3/envs/pyqt/lib/python3.11/http/client.py", line 1058, in _send_output
    self.send(msg)
  File "/Volumes/TOSHIBAEXT/opt/anaconda3/envs/pyqt/lib/python3.11/http/client.py", line 996, in send
    self.connect()
  File "/Volumes/TOSHIBAEXT/opt/anaconda3/envs/pyqt/lib/python3.11/site-packages/urllib3/connection.py", line 279, in connect
    self.sock = self._new_conn()
                ^^^^^^^^^^^^^^^^
  File "/Volumes/TOSHIBAEXT/opt/anaconda3/envs/pyqt/lib/python3.11/site-packages/urllib3/connection.py", line 214, in _new_conn
    raise NewConnectionError(
urllib3.exceptions.NewConnectionError: <urllib3.connection.HTTPConnection object at 0x117cac710>: Failed to establish a new connection: [Errno 61] Connection refused

The above exception was the direct cause of the following exception:

Traceback (most recent call last):
  File "/Volumes/TOSHIBAEXT/opt/anaconda3/envs/pyqt/lib/python3.11/site-packages/requests/adapters.py", line 667, in send
    resp = conn.urlopen(
           ^^^^^^^^^^^^^
  File "/Volumes/TOSHIBAEXT/opt/anaconda3/envs/pyqt/lib/python3.11/site-packages/urllib3/connectionpool.py", line 843, in urlopen
    retries = retries.increment(
              ^^^^^^^^^^^^^^^^^^
  File "/Volumes/TOSHIBAEXT/opt/anaconda3/envs/pyqt/lib/python3.11/site-packages/urllib3/util/retry.py", line 519, in increment
    raise MaxRetryError(_pool, url, reason) from reason  # type: ignore[arg-type]
    ^^^^^^^^^^^^^^^^^^^^^^^^^^^^^^^^^^^^^^^^^^^^^^^^^^^
urllib3.exceptions.MaxRetryError: HTTPConnectionPool(host='localhost', port=8000): Max retries exceeded with url: /security/scan (Caused by NewConnectionError('<urllib3.connection.HTTPConnection object at 0x117cac710>: Failed to establish a new connection: [Errno 61] Connection refused'))

During handling of the above exception, another exception occurred:

Traceback (most recent call last):
  File "/Users/lpcw/Documents/PyQt/PyExcelApp/main.py", line 51, in main
    security_scanner.check()
  File "/Users/lpcw/Documents/PyQt/PyExcelApp/dependency_monitoring_framework/src/services/security_scanner.py", line 17, in check
    response = requests.get(
               ^^^^^^^^^^^^^
  File "/Volumes/TOSHIBAEXT/opt/anaconda3/envs/pyqt/lib/python3.11/site-packages/requests/api.py", line 73, in get
    return request("get", url, params=params, **kwargs)
           ^^^^^^^^^^^^^^^^^^^^^^^^^^^^^^^^^^^^^^^^^^^^
  File "/Volumes/TOSHIBAEXT/opt/anaconda3/envs/pyqt/lib/python3.11/site-packages/requests/api.py", line 59, in request
    return session.request(method=method, url=url, **kwargs)
           ^^^^^^^^^^^^^^^^^^^^^^^^^^^^^^^^^^^^^^^^^^^^^^^^^
  File "/Volumes/TOSHIBAEXT/opt/anaconda3/envs/pyqt/lib/python3.11/site-packages/requests/sessions.py", line 589, in request
    resp = self.send(prep, **send_kwargs)
           ^^^^^^^^^^^^^^^^^^^^^^^^^^^^^^
  File "/Volumes/TOSHIBAEXT/opt/anaconda3/envs/pyqt/lib/python3.11/site-packages/requests/sessions.py", line 703, in send
    r = adapter.send(request, **kwargs)
        ^^^^^^^^^^^^^^^^^^^^^^^^^^^^^^^
  File "/Volumes/TOSHIBAEXT/opt/anaconda3/envs/pyqt/lib/python3.11/site-packages/requests/adapters.py", line 700, in send
    raise ConnectionError(e, request=request)
requests.exceptions.ConnectionError: HTTPConnectionPool(host='localhost', port=8000): Max retries exceeded with url: /security/scan (Caused by NewConnectionError('<urllib3.connection.HTTPConnection object at 0x117cac710>: Failed to establish a new connection: [Errno 61] Connection refused'))

2025-01-03 23:55:35,656 - root - INFO - Logging configured with level: INFO and file: logs/app.log
2025-01-03 23:55:36,726 - plugin_manager.utils.plugin_loader - INFO - 找到 2 个插件: ['xzltxs_test', 'xzltxs']
2025-01-03 23:55:58,394 - root - ERROR - 发生错误: HTTPSConnectionPool(host='security.dependency-check.org', port=443): Max retries exceeded with url: /api/v1/security/scan (Caused by NameResolutionError("<urllib3.connection.HTTPSConnection object at 0x11be6c9d0>: Failed to resolve 'security.dependency-check.org' ([Errno 8] nodename nor servname provided, or not known)"))
2025-01-03 23:55:58,395 - root - ERROR - 堆栈跟踪信息:
Traceback (most recent call last):
  File "/Volumes/TOSHIBAEXT/opt/anaconda3/envs/pyqt/lib/python3.11/site-packages/urllib3/connection.py", line 199, in _new_conn
    sock = connection.create_connection(
           ^^^^^^^^^^^^^^^^^^^^^^^^^^^^^
  File "/Volumes/TOSHIBAEXT/opt/anaconda3/envs/pyqt/lib/python3.11/site-packages/urllib3/util/connection.py", line 60, in create_connection
    for res in socket.getaddrinfo(host, port, family, socket.SOCK_STREAM):
               ^^^^^^^^^^^^^^^^^^^^^^^^^^^^^^^^^^^^^^^^^^^^^^^^^^^^^^^^^^
  File "/Volumes/TOSHIBAEXT/opt/anaconda3/envs/pyqt/lib/python3.11/socket.py", line 974, in getaddrinfo
    for res in _socket.getaddrinfo(host, port, family, type, proto, flags):
               ^^^^^^^^^^^^^^^^^^^^^^^^^^^^^^^^^^^^^^^^^^^^^^^^^^^^^^^^^^^
socket.gaierror: [Errno 8] nodename nor servname provided, or not known

The above exception was the direct cause of the following exception:

Traceback (most recent call last):
  File "/Volumes/TOSHIBAEXT/opt/anaconda3/envs/pyqt/lib/python3.11/site-packages/urllib3/connectionpool.py", line 789, in urlopen
    response = self._make_request(
               ^^^^^^^^^^^^^^^^^^^
  File "/Volumes/TOSHIBAEXT/opt/anaconda3/envs/pyqt/lib/python3.11/site-packages/urllib3/connectionpool.py", line 490, in _make_request
    raise new_e
  File "/Volumes/TOSHIBAEXT/opt/anaconda3/envs/pyqt/lib/python3.11/site-packages/urllib3/connectionpool.py", line 466, in _make_request
    self._validate_conn(conn)
  File "/Volumes/TOSHIBAEXT/opt/anaconda3/envs/pyqt/lib/python3.11/site-packages/urllib3/connectionpool.py", line 1095, in _validate_conn
    conn.connect()
  File "/Volumes/TOSHIBAEXT/opt/anaconda3/envs/pyqt/lib/python3.11/site-packages/urllib3/connection.py", line 693, in connect
    self.sock = sock = self._new_conn()
                       ^^^^^^^^^^^^^^^^
  File "/Volumes/TOSHIBAEXT/opt/anaconda3/envs/pyqt/lib/python3.11/site-packages/urllib3/connection.py", line 206, in _new_conn
    raise NameResolutionError(self.host, self, e) from e
urllib3.exceptions.NameResolutionError: <urllib3.connection.HTTPSConnection object at 0x11be6c9d0>: Failed to resolve 'security.dependency-check.org' ([Errno 8] nodename nor servname provided, or not known)

The above exception was the direct cause of the following exception:

Traceback (most recent call last):
  File "/Volumes/TOSHIBAEXT/opt/anaconda3/envs/pyqt/lib/python3.11/site-packages/requests/adapters.py", line 667, in send
    resp = conn.urlopen(
           ^^^^^^^^^^^^^
  File "/Volumes/TOSHIBAEXT/opt/anaconda3/envs/pyqt/lib/python3.11/site-packages/urllib3/connectionpool.py", line 843, in urlopen
    retries = retries.increment(
              ^^^^^^^^^^^^^^^^^^
  File "/Volumes/TOSHIBAEXT/opt/anaconda3/envs/pyqt/lib/python3.11/site-packages/urllib3/util/retry.py", line 519, in increment
    raise MaxRetryError(_pool, url, reason) from reason  # type: ignore[arg-type]
    ^^^^^^^^^^^^^^^^^^^^^^^^^^^^^^^^^^^^^^^^^^^^^^^^^^^
urllib3.exceptions.MaxRetryError: HTTPSConnectionPool(host='security.dependency-check.org', port=443): Max retries exceeded with url: /api/v1/security/scan (Caused by NameResolutionError("<urllib3.connection.HTTPSConnection object at 0x11be6c9d0>: Failed to resolve 'security.dependency-check.org' ([Errno 8] nodename nor servname provided, or not known)"))

During handling of the above exception, another exception occurred:

Traceback (most recent call last):
  File "/Users/lpcw/Documents/PyQt/PyExcelApp/main.py", line 51, in main
    security_scanner.check()
  File "/Users/lpcw/Documents/PyQt/PyExcelApp/dependency_monitoring_framework/src/services/security_scanner.py", line 17, in check
    response = requests.get(
               ^^^^^^^^^^^^^
  File "/Volumes/TOSHIBAEXT/opt/anaconda3/envs/pyqt/lib/python3.11/site-packages/requests/api.py", line 73, in get
    return request("get", url, params=params, **kwargs)
           ^^^^^^^^^^^^^^^^^^^^^^^^^^^^^^^^^^^^^^^^^^^^
  File "/Volumes/TOSHIBAEXT/opt/anaconda3/envs/pyqt/lib/python3.11/site-packages/requests/api.py", line 59, in request
    return session.request(method=method, url=url, **kwargs)
           ^^^^^^^^^^^^^^^^^^^^^^^^^^^^^^^^^^^^^^^^^^^^^^^^^
  File "/Volumes/TOSHIBAEXT/opt/anaconda3/envs/pyqt/lib/python3.11/site-packages/requests/sessions.py", line 589, in request
    resp = self.send(prep, **send_kwargs)
           ^^^^^^^^^^^^^^^^^^^^^^^^^^^^^^
  File "/Volumes/TOSHIBAEXT/opt/anaconda3/envs/pyqt/lib/python3.11/site-packages/requests/sessions.py", line 703, in send
    r = adapter.send(request, **kwargs)
        ^^^^^^^^^^^^^^^^^^^^^^^^^^^^^^^
  File "/Volumes/TOSHIBAEXT/opt/anaconda3/envs/pyqt/lib/python3.11/site-packages/requests/adapters.py", line 700, in send
    raise ConnectionError(e, request=request)
requests.exceptions.ConnectionError: HTTPSConnectionPool(host='security.dependency-check.org', port=443): Max retries exceeded with url: /api/v1/security/scan (Caused by NameResolutionError("<urllib3.connection.HTTPSConnection object at 0x11be6c9d0>: Failed to resolve 'security.dependency-check.org' ([Errno 8] nodename nor servname provided, or not known)"))

2025-01-03 23:57:53,169 - root - INFO - Logging configured with level: INFO and file: logs/app.log
2025-01-03 23:57:53,982 - plugin_manager.utils.plugin_loader - INFO - 找到 2 个插件: ['xzltxs_test', 'xzltxs']
2025-01-03 23:57:58,917 - root - ERROR - 发生错误: HTTPSConnectionPool(host='security.dependency-check.org', port=443): Max retries exceeded with url: /api/v1/security/scan (Caused by NameResolutionError("<urllib3.connection.HTTPSConnection object at 0x12c1ac710>: Failed to resolve 'security.dependency-check.org' ([Errno 8] nodename nor servname provided, or not known)"))
2025-01-03 23:57:58,918 - root - ERROR - 堆栈跟踪信息:
Traceback (most recent call last):
  File "/Volumes/TOSHIBAEXT/opt/anaconda3/envs/pyqt/lib/python3.11/site-packages/urllib3/connection.py", line 199, in _new_conn
    sock = connection.create_connection(
           ^^^^^^^^^^^^^^^^^^^^^^^^^^^^^
  File "/Volumes/TOSHIBAEXT/opt/anaconda3/envs/pyqt/lib/python3.11/site-packages/urllib3/util/connection.py", line 60, in create_connection
    for res in socket.getaddrinfo(host, port, family, socket.SOCK_STREAM):
               ^^^^^^^^^^^^^^^^^^^^^^^^^^^^^^^^^^^^^^^^^^^^^^^^^^^^^^^^^^
  File "/Volumes/TOSHIBAEXT/opt/anaconda3/envs/pyqt/lib/python3.11/socket.py", line 974, in getaddrinfo
    for res in _socket.getaddrinfo(host, port, family, type, proto, flags):
               ^^^^^^^^^^^^^^^^^^^^^^^^^^^^^^^^^^^^^^^^^^^^^^^^^^^^^^^^^^^
socket.gaierror: [Errno 8] nodename nor servname provided, or not known

The above exception was the direct cause of the following exception:

Traceback (most recent call last):
  File "/Volumes/TOSHIBAEXT/opt/anaconda3/envs/pyqt/lib/python3.11/site-packages/urllib3/connectionpool.py", line 789, in urlopen
    response = self._make_request(
               ^^^^^^^^^^^^^^^^^^^
  File "/Volumes/TOSHIBAEXT/opt/anaconda3/envs/pyqt/lib/python3.11/site-packages/urllib3/connectionpool.py", line 490, in _make_request
    raise new_e
  File "/Volumes/TOSHIBAEXT/opt/anaconda3/envs/pyqt/lib/python3.11/site-packages/urllib3/connectionpool.py", line 466, in _make_request
    self._validate_conn(conn)
  File "/Volumes/TOSHIBAEXT/opt/anaconda3/envs/pyqt/lib/python3.11/site-packages/urllib3/connectionpool.py", line 1095, in _validate_conn
    conn.connect()
  File "/Volumes/TOSHIBAEXT/opt/anaconda3/envs/pyqt/lib/python3.11/site-packages/urllib3/connection.py", line 693, in connect
    self.sock = sock = self._new_conn()
                       ^^^^^^^^^^^^^^^^
  File "/Volumes/TOSHIBAEXT/opt/anaconda3/envs/pyqt/lib/python3.11/site-packages/urllib3/connection.py", line 206, in _new_conn
    raise NameResolutionError(self.host, self, e) from e
urllib3.exceptions.NameResolutionError: <urllib3.connection.HTTPSConnection object at 0x12c1ac710>: Failed to resolve 'security.dependency-check.org' ([Errno 8] nodename nor servname provided, or not known)

The above exception was the direct cause of the following exception:

Traceback (most recent call last):
  File "/Volumes/TOSHIBAEXT/opt/anaconda3/envs/pyqt/lib/python3.11/site-packages/requests/adapters.py", line 667, in send
    resp = conn.urlopen(
           ^^^^^^^^^^^^^
  File "/Volumes/TOSHIBAEXT/opt/anaconda3/envs/pyqt/lib/python3.11/site-packages/urllib3/connectionpool.py", line 843, in urlopen
    retries = retries.increment(
              ^^^^^^^^^^^^^^^^^^
  File "/Volumes/TOSHIBAEXT/opt/anaconda3/envs/pyqt/lib/python3.11/site-packages/urllib3/util/retry.py", line 519, in increment
    raise MaxRetryError(_pool, url, reason) from reason  # type: ignore[arg-type]
    ^^^^^^^^^^^^^^^^^^^^^^^^^^^^^^^^^^^^^^^^^^^^^^^^^^^
urllib3.exceptions.MaxRetryError: HTTPSConnectionPool(host='security.dependency-check.org', port=443): Max retries exceeded with url: /api/v1/security/scan (Caused by NameResolutionError("<urllib3.connection.HTTPSConnection object at 0x12c1ac710>: Failed to resolve 'security.dependency-check.org' ([Errno 8] nodename nor servname provided, or not known)"))

During handling of the above exception, another exception occurred:

Traceback (most recent call last):
  File "/Users/lpcw/Documents/PyQt/PyExcelApp/main.py", line 51, in main
    security_scanner.check()
  File "/Users/lpcw/Documents/PyQt/PyExcelApp/dependency_monitoring_framework/src/services/security_scanner.py", line 17, in check
    response = requests.get(
               ^^^^^^^^^^^^^
  File "/Volumes/TOSHIBAEXT/opt/anaconda3/envs/pyqt/lib/python3.11/site-packages/requests/api.py", line 73, in get
    return request("get", url, params=params, **kwargs)
           ^^^^^^^^^^^^^^^^^^^^^^^^^^^^^^^^^^^^^^^^^^^^
  File "/Volumes/TOSHIBAEXT/opt/anaconda3/envs/pyqt/lib/python3.11/site-packages/requests/api.py", line 59, in request
    return session.request(method=method, url=url, **kwargs)
           ^^^^^^^^^^^^^^^^^^^^^^^^^^^^^^^^^^^^^^^^^^^^^^^^^
  File "/Volumes/TOSHIBAEXT/opt/anaconda3/envs/pyqt/lib/python3.11/site-packages/requests/sessions.py", line 589, in request
    resp = self.send(prep, **send_kwargs)
           ^^^^^^^^^^^^^^^^^^^^^^^^^^^^^^
  File "/Volumes/TOSHIBAEXT/opt/anaconda3/envs/pyqt/lib/python3.11/site-packages/requests/sessions.py", line 703, in send
    r = adapter.send(request, **kwargs)
        ^^^^^^^^^^^^^^^^^^^^^^^^^^^^^^^
  File "/Volumes/TOSHIBAEXT/opt/anaconda3/envs/pyqt/lib/python3.11/site-packages/requests/adapters.py", line 700, in send
    raise ConnectionError(e, request=request)
requests.exceptions.ConnectionError: HTTPSConnectionPool(host='security.dependency-check.org', port=443): Max retries exceeded with url: /api/v1/security/scan (Caused by NameResolutionError("<urllib3.connection.HTTPSConnection object at 0x12c1ac710>: Failed to resolve 'security.dependency-check.org' ([Errno 8] nodename nor servname provided, or not known)"))

2025-01-03 23:59:38,803 - root - INFO - Logging configured with level: INFO and file: logs/app.log
2025-01-03 23:59:39,605 - plugin_manager.utils.plugin_loader - INFO - 找到 2 个插件: ['xzltxs_test', 'xzltxs']
2025-01-03 23:59:50,364 - root - ERROR - 发生错误: 404 Client Error: Not Found for url: https://ossindex.sonatype.org/api/v3/security/scan
2025-01-03 23:59:50,365 - root - ERROR - 堆栈跟踪信息:
Traceback (most recent call last):
  File "/Users/lpcw/Documents/PyQt/PyExcelApp/main.py", line 51, in main
    security_scanner.check()
  File "/Users/lpcw/Documents/PyQt/PyExcelApp/dependency_monitoring_framework/src/services/security_scanner.py", line 21, in check
    response.raise_for_status()
  File "/Volumes/TOSHIBAEXT/opt/anaconda3/envs/pyqt/lib/python3.11/site-packages/requests/models.py", line 1024, in raise_for_status
    raise HTTPError(http_error_msg, response=self)
requests.exceptions.HTTPError: 404 Client Error: Not Found for url: https://ossindex.sonatype.org/api/v3/security/scan

